Workbook

Sheet US
A1: . | B1: æ | C1: Navn | D1: E-post | E1: Telefon | F1: Ønsket dato og tid for time | G1: Tannbleking? | H1: Status | I1: Antall kontaktpunkt | J1: Kommentar | K1: Leave this blank | L1: Source | M1: Ad Name | N1: Ad ID | O1: Label | P1: Count | Q1: gclid | R1: gbraid | S1: wbraid | U1: hashed_email | V1: timestamp | W1: fclid | X1: http refferrer | Y1: permalink url | Z1: post url | AA1: meta age range | AB1: meta gender | AC1: meta placement | AD1: meta device | AE1: meta ad format | AF1: google keyword | AG1: google device | AH1: google location | AI1: google network | AJ1: google placement | AK1: g ad group name | AL1: g creative id | AM1: OCT Uploaded | AN1: Conversion Value
A2: 46204 | B2: 21:02 | C2: ahmed | D2: ahmedmulla99@hotmail.com | E2: 41504225 | F2: August | H2: Ikke fått kontakt | I2: #1
A3: 46205 | B3: 00:06 | C3: Simon Solhem | D3: sfsolheim@gmail.com | E3: 98604319 | F3: Fredag 3. juli kl. 14-15 eller uke 31 | G3: Nei | H3: Booket til time | I3: #1
A4: 46205 | B4: 08:09 | C4: Susana P M Pinto | D4: suepinto@outlook.com | E4: 4794494310 | F4: Mandag 6.juli kl 9.00 | H4: Booket til time | I4: #1
A5: 46205 | B5: 12:01 | C5: Awa Sosseh | D5: yorbeh@gmail.com | E5: 462 24 758 | H5: Booket til time | I5: #1
A6: 46205 | B6: 16:49 | C6: Johan Norin | D6: johan.norin@hotmail.com | E6: 48344774 | F6: Tirdag 9 juli på morgonen | H6: Booket til time | I6: #1
A7: 46205 | B7: 18:30 | C7: Daray | D7: darayahmed@hotmail.com | E7: 97974415 | F7: Juni kl 21 | G7: Ja | H7: Ikke fått kontakt | I7: #1
A8: 46206 | B8: 00:33 | C8: Hai Ng | D8: balong_74@hotmail.com | E8: 40625721 | F8: Fredag 03.07.2026 | G8: Nei | H8: Booket til time | I8: #3
A9: 46206 | B9: 22:58 | C9: Fabian Castro | D9: fcastro989@yahoo.com | E9: 45487870 | F9: Torsdag 14:00 | G9: Usikker | H9: Booket til time | I9: #1
A10: 46207 | B10: 17:36 | C10: Jeanett | D10: bjerkejeanettproff@gmail.com | E10: 90595758 | F10: 15 juli | G10: Nei | H10: Booket til time | I10: #1
A11: 46209 | B11: 22:39 | C11: Waleed Abdullah Elmi Abtidon | D11: waleedabdala@hotmail.com | E11: 90219662 | F11: Mandag 13.juli mellom 10-16 | G11: Nei | H11: Booket til time | I11: #3
A12: 46210 | B12: 15:58 | C12: Nina Gundersen | D12: nina@fjellbo.net | E12: 4792622622 | F12: Fredag kl. 10.00 | H12: Ikke interessert | I12: #1 | J12: Har benyttet seg av tidligere
A13: 46210 | B13: 18:21 | C13: Aina Johansen | D13: ainajohansen@hotmail.com | E13: 91394608 | G13: Nei | H13: Booket til time | I13: #1
A14: 46211 | B14: 13:43 | C14: Steffan Satkunananthan | D14: steffan-sivaji@hotmail.com | E14: 96202446 | F14: Torsdag 9.juli. Tid: Når som helst | G14: Usikker | H14: Booket til time | I14: #1
A15: 46212 | B15: 16:42 | C15: Gilbert Catana | D15: gilcat3000@yahoo.no | E15: 97711967 | F15: 22 juli | G15: Ja | H15: Booket til time | I15: #1
A16: 46212 | B16: 19:32 | C16: Mohammad Hussein | D16: momi89@hotmail.com | E16: 99874462 | F16: tirdag kl. 14:00 | G16: Ja | H16: Ikke fått kontakt | I16: #2
A17: 46213 | B17: 04:41 | C17: Shiva Mohammadi | D17: shiva.1998@hotmail.com | E17: 47383951 | F17: Fredag 11. Juli etter kl 12 | G17: Usikker | H17: Ikke interessert | I17: #2
A18: 46213 | B18: 12:28 | C18: Vinnie Huser | D18: vinniehuser@hotmail.com | E18: 45030656 | F18: 21. juli ca kl 12 | G18: Usikker | H18: Booket til time | I18: #1
A19: 46213 | B19: 16:21 | C19: Sami Mohamed Abdi | D19: sabdi8514@gmail.com | E19: 48625157 | F19: Mandag 13. Juli kl 13:45 | G19: Usikker | H19: Ikke fått kontakt | I19: #2
A20: 46214 | B20: 20:04 | C20: Vaida Timinskaite | D20: vatimin@gmail.com | E20: 40053755 | G20: Nei | H20: Booket til time | I20: #1
G21: =IF(NOT(ISERROR(MATCH(D21,'Tannbleking - Oppsalg US'!D:D, 0))), "Ja", "")
G22: =IF(NOT(ISERROR(MATCH(D22,'Tannbleking - Oppsalg US'!D:D, 0))), "Ja", "")
G23: =IF(NOT(ISERROR(MATCH(D23,'Tannbleking - Oppsalg US'!D:D, 0))), "Ja", "")
G24: =IF(NOT(ISERROR(MATCH(D24,'Tannbleking - Oppsalg US'!D:D, 0))), "Ja", "")
G25: =IF(NOT(ISERROR(MATCH(D25,'Tannbleking - Oppsalg US'!D:D, 0))), "Ja", "")
G26: =IF(NOT(ISERROR(MATCH(D26,'Tannbleking - Oppsalg US'!D:D, 0))), "Ja", "")
G27: =IF(NOT(ISERROR(MATCH(D27,'Tannbleking - Oppsalg US'!D:D, 0))), "Ja", "")
G28: =IF(NOT(ISERROR(MATCH(D28,'Tannbleking - Oppsalg US'!D:D, 0))), "Ja", "")
G29: =IF(NOT(ISERROR(MATCH(D29,'Tannbleking - Oppsalg US'!D:D, 0))), "Ja", "")
G30: =IF(NOT(ISERROR(MATCH(D30,'Tannbleking - Oppsalg US'!D:D, 0))), "Ja", "")
G31: =IF(NOT(ISERROR(MATCH(D31,'Tannbleking - Oppsalg US'!D:D, 0))), "Ja", "")
G32: =IF(NOT(ISERROR(MATCH(D32,'Tannbleking - Oppsalg US'!D:D, 0))), "Ja", "")
... G134: =IF(NOT(ISERROR(MATCH(D134,'Tannbleking - Oppsalg US'!D:D, 0))), "Ja", "")

Sheet Historisk data
A1: 45931 | B1: 05:47 | C1: Zere Abraha Hiyabu | D1: zhiyabu@gmail.com | E1: 4748354835 | F1: onsdag 01.10.25 | G1: =IF(NOT(ISERROR(MATCH(D1,'Tannbleking - Oppsalg US'!D:D, 0))), "Ja", "") -> Ja | H1: Booket til time | I1: #1 | J1: Ønsker ikke bleking | L1: meta | M1: CV2010 | N1: 6843762966937 | O1: =TEXT(A1, "dd/mm/yyyy") -> 01/10/2025 | P1: =COUNTIFS(L:L,"meta",A:A,">="&DATE(2025,1,1),A:A,"<"&DATE(2026,1,1))+COUNTIFS(L:L,"ig",A:A,">="&DATE(2025,1,1),A:A,"<"&DATE(2026,1,1))+COUNTIFS(L:L,"fb",A:A,">="&DATE(2025,1,1),A:A,"<"&DATE(2026,1,1)) -> #ERROR! | U1: 10204b9133fdf0919149fb4ad082c5f6014f66394f5c7529498d4b9df5786bcc | V1: 2025-10-01T03:47:02+00:00 | X1: {post_referrer} | Y1: https://tannskjema.no | Z1: https://tannskjema.no/groruddalen-tannlegesenter | AC1: Facebook_Mobile_Feed
A2: 45931 | B2: 06:26 | C2: Malyun Mume | D2: saboontu88@hotmail.com | E2: 4747467165 | F2: 01.10.25 | G2: =IF(NOT(ISERROR(MATCH(D2,'Tannbleking - Oppsalg US'!D:D, 0))), "Ja", "") -> Ja | H2: Ikke fått kontakt | I2: #4 | J2: Nr er ikke i bruk | L2: meta | M2: CV2010 | N2: 6843762966937 | O2: =TEXT(A2, "dd/mm/yyyy") -> 01/10/2025 | P2: =COUNTIFS(L:L,"meta",H:H,"Booket til time",A:A,">="&DATE(2025,1,1),A:A,"<"&DATE(2026,1,1))+COUNTIFS(L:L,"ig",H:H,"Booket til time",A:A,">="&DATE(2025,1,1),A:A,"<"&DATE(2026,1,1))+COUNTIFS(L:L,"fb",H:H,"Booket til time",A:A,">="&DATE(2025,1,1),A:A,"<"&DATE(2026,1,1)) -> #ERROR! | U2: fbe909a6de5153e0bb9ca9b4fbfb0cc667b799ecf4210e24673ef49aa4b276fa | V2: 2025-10-01T04:26:16+00:00 | X2: {post_referrer} | Y2: https://tannskjema.no | Z2: https://tannskjema.no/groruddalen-tannlegesenter | AC2: Facebook_Mobile_Reels
A3: 45931 | B3: 06:46 | C3: Luiza Magdalena Przymenska | D3: lizetka@poczta.fm | E3: 4790976539 | F3: 07.10.2025 | G3: =IF(NOT(ISERROR(MATCH(D3,'Tannbleking - Oppsalg US'!D:D, 0))), "Ja", "") | H3: Booket til time | I3: #1 | L3: meta | M3: CV2010 | N3: 6843762966937 | O3: =TEXT(A3, "dd/mm/yyyy") -> 01/10/2025 | P3: =COUNTIFS(L:L,"meta",A:A,">="&DATE(2026,1,1),A:A,"<"&DATE(2026,4,1))+COUNTIFS(L:L,"ig",A:A,">="&DATE(2026,1,1),A:A,"<"&DATE(2026,4,1))+COUNTIFS(L:L,"fb",A:A,">="&DATE(2026,1,1),A:A,"<"&DATE(2026,4,1)) -> #ERROR! | U3: 74823fe411dee222006a4f5a9010cb0d66756060bbb1285402a874a9ae58f395 | V3: 2025-10-01T04:46:42+00:00 | X3: {post_referrer} | Y3: https://tannskjema.no | Z3: https://tannskjema.no/groruddalen-tannlegesenter | AC3: Facebook_Stories
A4: 45931 | B4: 07:07 | C4: Maybel Sisor | D4: may_lan26@yahoo.com | E4: 4745225235 | F4: 1.oktober | G4: =IF(NOT(ISERROR(MATCH(D4,'Tannbleking - Oppsalg US'!D:D, 0))), "Ja", "") | H4: Booket til time | I4: #1 | L4: meta | M4: CV2010 | N4: 6843762966937 | O4: =TEXT(A4, "dd/mm/yyyy") -> 01/10/2025 | P4: =COUNTIFS(L:L,"meta",H:H,"Booket til time",A:A,">="&DATE(2026,1,1),A:A,"<"&DATE(2026,4,1))+COUNTIFS(L:L,"ig",H:H,"Booket til time",A:A,">="&DATE(2026,1,1),A:A,"<"&DATE(2026,4,1))+COUNTIFS(L:L,"fb",H:H,"Booket til time",A:A,">="&DATE(2026,1,1),A:A,"<"&DATE(2026,4,1)) -> #ERROR! | T4: f4c6c39e6a9eff8dbc4c310c7d8e68d801385da58274f7711f2218a7c1569687 | U4: 229b8f66fb55a5edaf99ba63f409b65283bf4e50f4c8bcac5f4319582f82cd60 | V4: 2025-10-01T05:07:27+00:00 | X4: {post_referrer} | Y4: https://tannskjema.no | Z4: https://tannskjema.no/groruddalen-tannlegesenter | AC4: Facebook_Mobile_Feed
A5: 45931 | B5: 07:13 | C5: James Nguyen | D5: jamescong3@hotmail.com | E5: 4747335950 | F5: 07.10.2025 eller 09.10.2025 | G5: =IF(NOT(ISERROR(MATCH(D5,'Tannbleking - Oppsalg US'!D:D, 0))), "Ja", "") | H5: Ikke interessert | I5: #3 | J5: Telefonsvarer, fått kontakt men ønsker ikke likevel, vil dra til lillestrøm tannlege | L5: meta | M5: CV2010 | N5: 6843762966937 | O5: =TEXT(A5, "dd/mm/yyyy") -> 01/10/2025 | P5: =TO_UNIX_TIMESTAMP_DMY_HM(O5, B5) -> 1759302780 | T5: 40867c3899105e31b4193a6ac73feab8d518b579d09cc6998ad8698516ee4535 | U5: aeed86e644ed101dcbf0e21cf721e894aeb1961066f9fc3f5da9e40ac3b89bb2 | V5: 2025-10-01T05:13:29+00:00 | X5: {post_referrer} | Y5: https://tannskjema.no | Z5: https://tannskjema.no/groruddalen-tannlegesenter | AC5: Facebook_Mobile_Feed
A6: 45932 | B6: 08:06 | C6: Claudio Solano Josefina | D6: josefina-solano@hitmail.com | E6: 4798448385 | F6: 14.10.25 | G6: =IF(NOT(ISERROR(MATCH(D6,'Tannbleking - Oppsalg US'!D:D, 0))), "Ja", "") | H6: Booket til time | I6: #1 | L6: meta | M6: CV2010 | N6: 6843762966937 | O6: =TEXT(A6, "dd/mm/yyyy") -> 02/10/2025 | P6: =TO_UNIX_TIMESTAMP_DMY_HM(O6, B6) -> 1759392360 | T6: 3e9f39b15150d71f0ca07ef0671ea78d325467a788d9e6d8f291fb7018c8a8bc | U6: 0a7595682192f46d2d5922f24e5f506a8f556dcbbbb201222526ed75d3373282 | V6: 2025-10-02T06:06:27+00:00 | X6: {post_referrer} | Y6: https://tannskjema.no | Z6: https://tannskjema.no/groruddalen-tannlegesenter | AC6: Facebook_Mobile_Reels
A7: 45932 | B7: 08:47 | C7: Dipak Shrestha | D7: just.dipak123@gmail.com | E7: 4746261486 | F7: Ja idag | G7: =IF(NOT(ISERROR(MATCH(D7,'Tannbleking - Oppsalg US'!D:D, 0))), "Ja", "") | H7: Booket til time | I7: #1 | L7: meta | M7: CV9802 | N7: 6843815997337 | O7: =TEXT(A7, "dd/mm/yyyy") -> 02/10/2025 | P7: =TO_UNIX_TIMESTAMP_DMY_HM(O7, B7) -> 1759394820 | T7: 9c74615fae98eedd34e251256ffc3799ef3095519f25d953d8d98c079d1abc3c | U7: 13c91de035e87d9623b6ffcd1c2afcf2dddc39d84cf56314ffc703512cdc45b8 | V7: 2025-10-02T06:47:23+00:00 | X7: {post_referrer} | Y7: https://tannskjema.no | Z7: https://tannskjema.no/groruddalen-tannlegesenter | AC7: Facebook_Mobile_Feed
A8: 45932 | B8: 08:53 | C8: Mirtha Ledy De León Núñez | D8: kattydeleon25@gmail.com | E8: 4741069170 | F8: 18.1 | G8: =IF(NOT(ISERROR(MATCH(D8,'Tannbleking - Oppsalg US'!D:D, 0))), "Ja", "") | H8: Booket til time | I8: #1 | L8: meta | M8: CV2010 | N8: 6843762966937 | O8: =TEXT(A8, "dd/mm/yyyy") -> 02/10/2025 | P8: =TO_UNIX_TIMESTAMP_DMY_HM(O8, B8) -> 1759395180 | T8: 7232be2f02ab55f140cc40f412686339659d8c375f0ae29c6f32ef050a3ae044 | U8: 26e8e64e9e6d30cd9df91a2eba7862286bd422694ddcb1d935975dd1f82e6813 | V8: 2025-10-02T06:53:07+00:00 | X8: {post_referrer} | Y8: https://tannskjema.no | Z8: https://tannskjema.no/groruddalen-tannlegesenter | AC8: Facebook_Mobile_Reels
A9: 45932 | B9: 08:54 | C9: Randy Calapini Raynon | D9: pok.pok_ako08@yahoo.com | E9: 4741358698 | F9: 07.10.2025 | G9: =IF(NOT(ISERROR(MATCH(D9,'Tannbleking - Oppsalg US'!D:D, 0))), "Ja", "") | H9: Booket til time | I9: #3 | J9: Telefonsvarer - Ringer, men ingen svar | L9: meta | M9: CV2010 | N9: 6843762966937 | O9: =TEXT(A9, "dd/mm/yyyy") -> 02/10/2025 | P9: =TO_UNIX_TIMESTAMP_DMY_HM(O9, B9) -> 1759395240 | T9: 173657510a54f01b219918479b9ac6a3e50c44a33d384a898647a63d14394776 | U9: 37d96664ef0248a653e1e08c9e3f5f26c2544db423a0b63ea03c4c8ffdf07568 | V9: 2025-10-02T06:54:05+00:00 | X9: {post_referrer} | Y9: https://tannskjema.no | Z9: https://tannskjema.no/groruddalen-tannlegesenter | AC9: Facebook_Mobile_Feed
A10: 45932 | B10: 11:34 | C10: Sana Balal | D10: sanabalal24@gmail.com | E10: 4746726180 | F10: Neste uke mellom 10 og 12 på dagen | G10: =IF(NOT(ISERROR(MATCH(D10,'Tannbleking - Oppsalg US'!D:D, 0))), "Ja", "") | H10: Booket til time | I10: #1 | L10: meta | M10: CV2010 | N10: 6843762966937 | O10: =TEXT(A10, "dd/mm/yyyy") -> 02/10/2025 | P10: =TO_UNIX_TIMESTAMP_DMY_HM(O10, B10) -> 1759404840 | T10: 669bf853f69a6227ab158b7addec0099313e90e221dbc03ebf6bfe48c34e04ae | U10: 9fe1c69066345b75af26e0ed86ca90d8b59b9568b4ad37797747a4628a686f67 | V10: 2025-10-02T09:34:05+00:00 | X10: {post_referrer} | Y10: https://tannskjema.no | Z10: https://tannskjema.no/groruddalen-tannlegesenter | AC10: Facebook_Mobile_Feed
A11: 45933 | B11: 08:27 | C11: Djamel Allam | D11: eddineallam@hotmail.com | E11: 4794213661 | F11: Lørdag kl 12h | G11: =IF(NOT(ISERROR(MATCH(D11,'Tannbleking - Oppsalg US'!D:D, 0))), "Ja", "") | H11: Booket til time | I11: #1 | L11: meta | M11: CV2010 | N11: 6843762966937 | O11: =TEXT(A11, "dd/mm/yyyy") -> 03/10/2025 | P11: =TO_UNIX_TIMESTAMP_DMY_HM(O11, B11) -> 1759480020 | T11: 6147fae89bd011a5b0858903b6f8f2827363f32a3746bfc7f1bbf01b5f50dd51 | U11: 51d78c67682bb926834c4ea912bfb7659624006ca996baefc4bf65413adea2db | V11: 2025-10-03T06:27:08+00:00 | X11: {post_referrer} | Y11: https://tannskjema.no | Z11: https://tannskjema.no/groruddalen-tannlegesenter | AC11: Facebook_Mobile_Feed
A12: 45934 | B12: 01:22 | C12: Kijare | D12: frangu_k@hotmail.com | E12: 4793033441 | F12: 07.10.25 | G12: =IF(NOT(ISERROR(MATCH(D12,'Tannbleking - Oppsalg US'!D:D, 0))), "Ja", "") | H12: Booket til time | I12: #1 | L12: meta | M12: CV2010 | N12: 6843762966937 | O12: =TEXT(A12, "dd/mm/yyyy") -> 04/10/2025 | P12: =TO_UNIX_TIMESTAMP_DMY_HM(O12, B12) -> 1759540920 | T12: 449b2d267c70f56a3b907117c30ed1affb24fb6b9d7ae65f2238a497a1e468af | U12: 1316d76069592906e57a4184152cb93558794817a9f89bfcbcaae2b8a012c867 | V12: 2025-10-03T23:22:25+00:00 | X12: {post_referrer} | Y12: https://tannskjema.no | Z12: https://tannskjema.no/groruddalen-tannlegesenter | AC12: Facebook_Mobile_Reels
A13: 45934 | B13: 06:44 | C13: Titti Bjørk | D13: titti1366@gmail.com | E13: 4.4654161774654E+17 | F13: 19.1 | G13: =IF(NOT(ISERROR(MATCH(D13,'Tannbleking - Oppsalg US'!D:D, 0))), "Ja", "") | H13: Ikke fått kontakt | J13: Nr stemmer ikke, sendt mail venter på svar. | L13: meta | M13: CV2010 | N13: 6843762966937 | O13: =TEXT(A13, "dd/mm/yyyy") -> 04/10/2025 | P13: =TO_UNIX_TIMESTAMP_DMY_HM(O13, B13) -> 1759560240 | T13: b6ff9b901ccde8f154d3c4d250c8b2e66a500df2b17adf500c3c02aaed6218a2 | U13: 0994ee2cda8b4688bb329bc8a2988ffcbc6955294ac3d8b2ec0dede142d2b39f | V13: 2025-10-04T04:44:55+00:00 | X13: {post_referrer} | Y13: https://tannskjema.no | Z13: https://tannskjema.no/groruddalen-tannlegesenter | AC13: Facebook_Mobile_Reels
A14: 45934 | B14: 11:55 | C14: Kristine Møkleby | D14: kristinemokleby@gmail.com | E14: 4793898261 | F14: 9 oktober | G14: =IF(NOT(ISERROR(MATCH(D14,'Tannbleking - Oppsalg US'!D:D, 0))), "Ja", "") | H14: Booket til time | I14: #4 | J14: Tok ikke opp tlf, mobil var avskrudd på forsøk 3. | L14: meta | M14: CV2014 | N14: 6843809343537 | O14: =TEXT(A14, "dd/mm/yyyy") -> 04/10/2025 | P14: =TO_UNIX_TIMESTAMP_DMY_HM(O14, B14) -> 1759578900 | T14: 1604aece86b249182ae76e567fa050135562c38ce2f1f87e682449cf0826f3a4 | U14: d870a174a60d85d7223fb047bc4f64adf3d991ba8a59d0b1e5c18983a2bd6e29 | V14: 2025-10-04T09:55:17+00:00 | X14: {post_referrer} | Y14: https://tannskjema.no | Z14: https://tannskjema.no/groruddalen-tannlegesenter | AC14: Facebook_Mobile_Feed
A15: 45935 | B15: 11:44 | C15: tender lay | D15: tenderlay@yahoo.no | E15: 4745524883 | F15: Lørdag | G15: =IF(NOT(ISERROR(MATCH(D15,'Tannbleking - Oppsalg US'!D:D, 0))), "Ja", "") | H15: Booket til time | I15: #2 | L15: meta | M15: CV2015 | N15: 6843809575737 | O15: =TEXT(A15, "dd/mm/yyyy") -> 05/10/2025 | P15: =TO_UNIX_TIMESTAMP_DMY_HM(O15, B15) -> 1759664640 | T15: 9087880331edb524202c12623f2ca38292c370c01a7bfdca9369221594c936fb | U15: 0b00ceeced404ded4b0b678355dce1cb9d19a10c94bf069712f5d42909070558 | V15: 2025-10-05T09:44:30+00:00 | X15: {post_referrer} | Y15: https://tannskjema.no | Z15: https://tannskjema.no/groruddalen-tannlegesenter | AC15: Facebook_Mobile_Feed
A16: 45936 | B16: 02:26 | C16: Yonas Haylom | D16: adibaro@hotmail.com | E16: 4798079851 | F16: Tirsdag | G16: =IF(NOT(ISERROR(MATCH(D16,'Tannbleking - Oppsalg US'!D:D, 0))), "Ja", "") -> Ja | H16: Ikke interessert | J16: Ringt 06.10.2025 kl 08:35 | L16: meta | M16: CV2015 | N16: 6843809575737 | O16: =TEXT(A16, "dd/mm/yyyy") -> 06/10/2025 | P16: =TO_UNIX_TIMESTAMP_DMY_HM(O16, B16) -> 1759717560 | T16: b326bf18851133c2a0deb8c73f553171ebc4fa805ff67012de1a9d8c46b7be64 | U16: 03f568c9d68679ed15c89c63ff0ca46090d42a4a45a015e3c9abb489de362149 | V16: 2025-10-06T00:26:58+00:00 | X16: {post_referrer} | Y16: https://tannskjema.no | Z16: https://tannskjema.no/groruddalen-tannlegesenter | AC16: Facebook_Mobile_Reels
A17: 45936 | B17: 06:45 | C17: Katherine Lumban | D17: jaykatlumban@yahoo.com | E17: 4741348438 | F17: 13.1 | G17: =IF(NOT(ISERROR(MATCH(D17,'Tannbleking - Oppsalg US'!D:D, 0))), "Ja", "") | H17: Ikke interessert | J17: Ringt 06.10.2025 kl 08:30 | L17: meta | M17: CV2015 | N17: 6843809575737 | O17: =TEXT(A17, "dd/mm/yyyy") -> 06/10/2025 | P17: =TO_UNIX_TIMESTAMP_DMY_HM(O17, B17) -> 1759733100 | T17: 29cea2e9870be91e64854cf15b02ff29bf122a79e3e594e38b08fbea4ba54ba6 | U17: 2123053718293ffcbb5d0f6525222adedf2556e3a7908e804c51df8f80e670e4 | V17: 2025-10-06T04:46:01+00:00 | X17: {post_referrer} | Y17: https://tannskjema.no | Z17: https://tannskjema.no/groruddalen-tannlegesenter | AC17: Facebook_Mobile_Feed
A18: 45936 | B18: 07:56 | C18: Zaghum Abbas | D18: abbaszaghum6@gmail.com | E18: 4740626688 | F18: 7/10/2025/. Time. 17:30 | G18: =IF(NOT(ISERROR(MATCH(D18,'Tannbleking - Oppsalg US'!D:D, 0))), "Ja", "") | H18: Booket til time | L18: meta | M18: CV2015 | N18: 6843809575737 | O18: =TEXT(A18, "dd/mm/yyyy") -> 06/10/2025 | P18: =TO_UNIX_TIMESTAMP_DMY_HM(O18, B18) -> 1759737360 | T18: fbb03b7cda497b17df5853c54a889057c83c2638f8ec7b4d4722e4d17594363e | U18: 66e678b142ec9429e89ef664407a38484dcddcbd107c29686c9e6610e50f3cb5 | V18: 2025-10-06T05:56:19+00:00 | X18: {post_referrer} | Y18: https://tannskjema.no | Z18: https://tannskjema.no/groruddalen-tannlegesenter | AC18: Facebook_Mobile_Reels
A19: 45936 | B19: 13:20 | C19: Jocelyn Aban Ibanez | D19: boss_ibanez@hotmail.com | E19: 4790930895 | F19: 08.oktober.2025 | G19: =IF(NOT(ISERROR(MATCH(D19,'Tannbleking - Oppsalg US'!D:D, 0))), "Ja", "") | H19: Booket til time | L19: meta | M19: CV2015 | N19: 6843809575737 | O19: =TEXT(A19, "dd/mm/yyyy") -> 06/10/2025 | P19: =TO_UNIX_TIMESTAMP_DMY_HM(O19, B19) -> 1759756800 | T19: 23b9cafca9c97a9f3aff2f5108a9634b4eaebc58e089b0d89e87501c2a1040a0 | U19: ddd1bf808779506f476d0d0d6ed156890ae5544b242379dda0daeec2d155f0bd | V19: 2025-10-06T11:20:10+00:00 | X19: {post_referrer} | Y19: https://tannskjema.no | Z19: https://tannskjema.no/groruddalen-tannlegesenter | AC19: Facebook_Mobile_Feed
A20: 45937 | B20: 11:06 | C20: Sugirtha Baskaran | D20: sugirt3003@gmail.com | E20: 4748509122 | F20: 14/16 oktober | G20: =IF(NOT(ISERROR(MATCH(D20,'Tannbleking - Oppsalg US'!D:D, 0))), "Ja", "") | H20: Booket til time | I20: #2 | L20: meta | M20: CV2015 | N20: 6843809575737 | O20: =TEXT(A20, "dd/mm/yyyy") -> 07/10/2025 | P20: =TO_UNIX_TIMESTAMP_DMY_HM(O20, B20) -> 1759835160 | T20: 5ddf661511c15d54d6a04158a6cd1a62c7f5d031769dd4e08b0f279288a30927 | U20: f862a2f3424f83c572b70a2f8e6db6a72f62175b837b108beb499525f240af58 | V20: 2025-10-07T09:06:24+00:00 | X20: {post_referrer} | Y20: https://tannskjema.no | Z20: https://tannskjema.no/groruddalen-tannlegesenter | AC20: Instagram_Reels
A21: 45937 | B21: 21:56 | C21: abdullahi yusif | D21: ayhir@hotmail.com | E21: 4745812733 | F21: 10.1025 | G21: =IF(NOT(ISERROR(MATCH(D21,'Tannbleking - Oppsalg US'!D:D, 0))), "Ja", "") | H21: Booket til time | I21: #2 | O21: =TEXT(A21, "dd/mm/yyyy") -> 07/10/2025 | P21: =TO_UNIX_TIMESTAMP_DMY_HM(O21, B21) -> 1759874160 | T21: b6d61b56b6a080336e01903c6a06395c244f571206fc476536f65b45b6ad95b4 | U21: f7edd8e6347ff6ca660168499f62434b40bf154c611ab05b9e2b41d7fef3d0c6 | V21: 2025-10-07T19:56:31+00:00 | X21: {post_referrer} | Y21: https://tannskjema.no | Z21: https://tannskjema.no/groruddalen-tannlegesenter
A22: 45938 | B22: 06:18 | C22: Samuel Gomes | D22: samuelgomes1984norge@gmail.com | E22: 4745562850 | F22: 10/10/2025 14:30 | G22: =IF(NOT(ISERROR(MATCH(D22,'Tannbleking - Oppsalg US'!D:D, 0))), "Ja", "") | H22: Booket til time | I22: #1 | L22: meta | M22: CV2015 | N22: 6843809575737 | O22: =TEXT(A22, "dd/mm/yyyy") -> 08/10/2025 | P22: =TO_UNIX_TIMESTAMP_DMY_HM(O22, B22) -> 1759904280 | T22: 3f5c96b3a8e66d37f12e1b9407b0088d0e03df3148f4ff3ef25c9b2b924acfd5 | U22: 70dd11c81bd869423d0f8cf4b86e36935f45e2d9215f32338f189ab9e449438e | V22: 2025-10-08T04:18:03+00:00 | X22: {post_referrer} | Y22: https://tannskjema.no | Z22: https://tannskjema.no/groruddalen-tannlegesenter | AC22: Facebook_Mobile_Reels
A23: 45938 | B23: 11:46 | C23: Vezir Veziri | D23: vezir_jajovski@hotmail.com | E23: 90831492 | F23: 14 okt. | G23: =IF(NOT(ISERROR(MATCH(D23,'Tannbleking - Oppsalg US'!D:D, 0))), "Ja", "") | H23: Booket til time | I23: #1 | J23: Pasienten ringte opp selv og satte opp time | L23: meta | M23: CV2016 | N23: 6843810044537 | O23: =TEXT(A23, "dd/mm/yyyy") -> 08/10/2025 | P23: =TO_UNIX_TIMESTAMP_DMY_HM(O23, B23) -> 1759923960 | T23: 4589237f0094fe9ca290b9628effd959add39254ead17b753fbfa79531bd64c8 | U23: eb98084531b9a7a8c770ad282dbe04b41aaa24d50b06f8e0131ec17402606121 | V23: 2025-10-08T09:46:11+00:00 | X23: {post_referrer} | Y23: https://tannskjema.no | Z23: https://tannskjema.no/groruddalen-tannlegesenter | AC23: Facebook_Mobile_Feed
A24: 45938 | B24: 15:29 | C24: Ali Haider | D24: ali.haider.a1@hotmail.com | E24: 4790246467 | F24: 10 oktober kl 12 | G24: =IF(NOT(ISERROR(MATCH(D24,'Tannbleking - Oppsalg US'!D:D, 0))), "Ja", "") | H24: Booket til time | I24: #3 | L24: meta | M24: CV2015 | N24: 6843809575737 | O24: =TEXT(A24, "dd/mm/yyyy") -> 08/10/2025 | P24: =TO_UNIX_TIMESTAMP_DMY_HM(O24, B24) -> 1759937340 | T24: 68c9d3d9cac43cf835d46527b85b3ada7ecc707fc1a4110cdb18ea246769d551 | U24: 83a0f0ff2ccde6739fdff979669da83592e4ffb1d737ee6b371de2bbfbe6dcc0 | V24: 2025-10-08T13:29:49+00:00 | X24: {post_referrer} | Y24: https://tannskjema.no | Z24: https://tannskjema.no/groruddalen-tannlegesenter | AC24: Instagram_Reels
A25: 45939 | B25: 01:59 | C25: Sajjad Ahmad | D25: sajjad.ahmad333@gmail.com | E25: 4791243924 | F25: 13/10 mandag etter kl 13 | G25: =IF(NOT(ISERROR(MATCH(D25,'Tannbleking - Oppsalg US'!D:D, 0))), "Ja", "") | H25: Booket til time | I25: #1 | L25: meta | M25: CV2015 | N25: 6843809575737 | O25: =TEXT(A25, "dd/mm/yyyy") -> 09/10/2025 | P25: =TO_UNIX_TIMESTAMP_DMY_HM(O25, B25) -> 1759975140 | T25: 71a12ce70b298f7f2f012c2844e53148ebc44052963e63342b409babcc7e48b1 | U25: f9b2d0a6b7cf6be8d236fc2b6e9aca178d493e8bb52560e5ee1645fb8782079d | V25: 2025-10-08T23:59:09+00:00 | X25: {post_referrer} | Y25: https://tannskjema.no | Z25: https://tannskjema.no/groruddalen-tannlegesenter | AC25: Facebook_Mobile_Reels
A26: 45939 | B26: 09:41 | C26: Enise Akdeniz | D26: enise.akdeniz@yahoo.com | E26: 4791916543 | F26: Mandager eller torsdager kl 18-19 | G26: =IF(NOT(ISERROR(MATCH(D26,'Tannbleking - Oppsalg US'!D:D, 0))), "Ja", "") | H26: Booket til time | I26: #5 | J26: Sendt mail | L26: meta | M26: CV2015 | N26: 6843809575737 | O26: =TEXT(A26, "dd/mm/yyyy") -> 09/10/2025 | P26: =TO_UNIX_TIMESTAMP_DMY_HM(O26, B26) -> 1760002860 | T26: 0e289ebcd936320574f16b2881d4bf836614a804abe7429bff35dd7a50c031fb | U26: 12052f6660187b1f7f057665021b20978e10051c058636e85ec9caf5d2d49fa4 | V26: 2025-10-09T07:41:43+00:00 | X26: {post_referrer} | Y26: https://tannskjema.no | Z26: https://tannskjema.no/groruddalen-tannlegesenter | AC26: Facebook_Mobile_Feed
A27: 45939 | B27: 10:40 | C27: Mohammed EL Messaouri | D27: moha_el93@hotmail.com | E27: 4798999440 | F27: Uke dager på kvelden eller helg når som helst | G27: =IF(NOT(ISERROR(MATCH(D27,'Tannbleking - Oppsalg US'!D:D, 0))), "Ja", "") | H27: Ikke interessert | I27: #1 | J27: Har bestilt time to ganger, ikke møtt begge gangene. | L27: meta | M27: CV9802 | N27: 6843815997337 | O27: =TEXT(A27, "dd/mm/yyyy") -> 09/10/2025 | P27: =TO_UNIX_TIMESTAMP_DMY_HM(O27, B27) -> 1760006400 | T27: 03a0a62b7d964597ef7783a62b6b711d29bc3530f7076752d24880b853b20fe1 | U27: 8bc74441c6fba8ee57b0b1f2eb807b19019943dc539bc2e7742b8433151e0b40 | V27: 2025-10-09T08:40:29+00:00 | X27: {post_referrer} | Y27: https://tannskjema.no | Z27: https://tannskjema.no/groruddalen-tannlegesenter | AC27: Facebook_Mobile_Feed
A28: 45940 | B28: 00:58 | C28: Razia hashemi | D28: razia.barakatullah@gmail.com | E28: 4794237778 | F28: Ønsker tirsdag 14 oktober | G28: =IF(NOT(ISERROR(MATCH(D28,'Tannbleking - Oppsalg US'!D:D, 0))), "Ja", "") | H28: Booket til time | I28: #4 | L28: meta | M28: CV2015 | N28: 6843809575737 | O28: =TEXT(A28, "dd/mm/yyyy") -> 10/10/2025 | P28: =TO_UNIX_TIMESTAMP_DMY_HM(O28, B28) -> 1760057880 | T28: 29a5a128a9c7a8e2a3ef7a739931700c1a75c3ba45c6b24118baf7b87d35e35e | U28: 97272c75e7d1949d3c43ea1d16dd5af84518c1efa43d09ce800fdba549afe312 | V28: 2025-10-09T22:58:15+00:00 | X28: {post_referrer} | Y28: https://tannskjema.no | Z28: https://tannskjema.no/groruddalen-tannlegesenter | AC28: Facebook_Mobile_Feed
A29: 45940 | B29: 12:40 | C29: Tine Pedersen | D29: tinep86@hotmail.com | E29: 4793680400 | F29: torsdag 16.10.2025 | G29: =IF(NOT(ISERROR(MATCH(D29,'Tannbleking - Oppsalg US'!D:D, 0))), "Ja", "") -> Ja | H29: Ikke interessert | I29: #3 | L29: fb | M29: 6843809575737 | O29: =TEXT(A29, "dd/mm/yyyy") -> 10/10/2025 | P29: =TO_UNIX_TIMESTAMP_DMY_HM(O29, B29) -> 1760100000 | T29: d751e9c126b7d2a7e1497bcf30f3483d2cb53b896a0420157aa23da5769b1f3e | U29: cae54722fd2045b4da071bafa83dc1cd9a4ea61fe42a71a89ac0428078e80dae | V29: 2025-10-10T10:40:19+00:00 | X29: {post_referrer} | Y29: https://tannskjema.no | Z29: https://tannskjema.no/groruddalen-tannlegesenter
A30: 45941 | B30: 15:33 | C30: Hedieh Saidi | D30: hedieh84@icloud.com | E30: 4740673065 | F30: 28 | G30: =IF(NOT(ISERROR(MATCH(D30,'Tannbleking - Oppsalg US'!D:D, 0))), "Ja", "") | H30: Ikke interessert | I30: #1 | J30: Satt opp time og avbestilt | L30: meta | M30: CV2010 | N30: 6843762966937 | O30: =TEXT(A30, "dd/mm/yyyy") -> 11/10/2025 | P30: =TO_UNIX_TIMESTAMP_DMY_HM(O30, B30) -> 1760196780 | T30: 2b85c1e34fa756e7ebc6c1f61597cbd848743eaf3e63304c16fdd76ed875a67e | U30: 10007de4ecb555f0f5b4b094339c5eb3c3f30fb2fc65dd922df8d36dfb0e1615 | V30: 2025-10-11T13:33:50+00:00 | X30: {post_referrer} | Y30: https://tannskjema.no | Z30: https://tannskjema.no/groruddalen-tannlegesenter | AC30: Instagram_Reels
A31: 45941 | B31: 16:36 | C31: Henriette Aud Harriett Bjørke | D31: ahbjor@gmail.com | E31: 4790277934 | F31: Tirsdag | G31: =IF(NOT(ISERROR(MATCH(D31,'Tannbleking - Oppsalg US'!D:D, 0))), "Ja", "") | H31: Ikke interessert | I31: #1 | J31: Ringte og sa hun ikke var interessert likevel | L31: meta | M31: CV2010 | N31: 6843762966937 | O31: =TEXT(A31, "dd/mm/yyyy") -> 11/10/2025 | P31: =TO_UNIX_TIMESTAMP_DMY_HM(O31, B31) -> 1760200560 | T31: fdcb64163cec6356e4713788df2c29e4ee31655bf5b96e8b423438d644eec94b | U31: 89c8aeb05e08a5dbf047f7ea62f1d3e8e12187dfbf07b687164aab74a28b2c07 | V31: 2025-10-11T14:36:10+00:00 | X31: {post_referrer} | Y31: https://tannskjema.no | Z31: https://tannskjema.no/groruddalen-tannlegesenter | AC31: Facebook_Mobile_Reels
A32: 45941 | B32: 20:58 | C32: Rasul Golam | D32: norge_22@icloud.com | E32: 4740474097 | F32: 15.10.25 | G32: =IF(NOT(ISERROR(MATCH(D32,'Tannbleking - Oppsalg US'!D:D, 0))), "Ja", "") | H32: Booket til time | I32: #4 | L32: meta | M32: CV2010 | N32: 6843762966937 | O32: =TEXT(A32, "dd/mm/yyyy") -> 11/10/2025 | P32: =TO_UNIX_TIMESTAMP_DMY_HM(O32, B32) -> 1760216280 | T32: 0038d84b139a83e16e72512471622e5fd2210a1de00770cdd981e4118a41422a | U32: 0cf3c9f81969be630331674f1d8d66da07562fd74d698750298fdd6969f6ea94 | V32: 2025-10-11T18:58:55+00:00 | X32: {post_referrer} | Y32: https://tannskjema.no | Z32: https://tannskjema.no/groruddalen-tannlegesenter | AC32: Facebook_Mobile_Feed
A33: 45942 | B33: 00:43 | C33: Ismail Traore | D33: ismail.traore@barrum.kommune.no | E33: 4799872212 | F33: Lørdag 18.10.25 kl 12 | G33: =IF(NOT(ISERROR(MATCH(D33,'Tannbleking - Oppsalg US'!D:D, 0))), "Ja", "") | H33: Booket til time | I33: #4 | J33: Rett til telefonsvarer, ingen svar på forsøk 3, sier han ringer tilbake på forsø 4 | L33: meta | M33: CV2010 | N33: 6843762966937 | O33: =TEXT(A33, "dd/mm/yyyy") -> 12/10/2025 | P33: =TO_UNIX_TIMESTAMP_DMY_HM(O33, B33) -> 1760229780 | T33: 7e256eebc74c169c2cb203d778d596e46fc6a7ff77d2a050d369a3e467fbec93 | U33: 975529ac4d301ec12820e5dd255c24cd0c2201f8252de157bf2ea095f826548c | V33: 2025-10-11T22:43:49+00:00 | X33: {post_referrer} | Y33: https://tannskjema.no | Z33: https://tannskjema.no/groruddalen-tannlegesenter | AC33: Facebook_Mobile_Feed
A34: 45942 | B34: 02:04 | C34: Nazia Sultana | D34: nsa_83@hotmail.com | E34: 4792604020 | F34: 20 oktober | G34: =IF(NOT(ISERROR(MATCH(D34,'Tannbleking - Oppsalg US'!D:D, 0))), "Ja", "") | H34: Booket til time | I34: #1 | L34: meta | M34: CV2010 | N34: 6843762966937 | O34: =TEXT(A34, "dd/mm/yyyy") -> 12/10/2025 | P34: =TO_UNIX_TIMESTAMP_DMY_HM(O34, B34) -> 1760234640 | T34: 72e4065b7ed8ab427572b80eed796cabc59037920b299cfc655435868c9b5b7a | U34: 67b4a2a4d5bf1f952570eed5042328dd1f1d296b7e4c08e483cfd1d015840dc3 | V34: 2025-10-12T00:04:16+00:00 | X34: {post_referrer} | Y34: https://tannskjema.no | Z34: https://tannskjema.no/groruddalen-tannlegesenter | AC34: Facebook_Mobile_Feed
A35: 45943 | B35: 12:17 | C35: Amer Ali Alam | D35: amer_89@hotmail.no | E35: 4795551755 | F35: Idag? | G35: =IF(NOT(ISERROR(MATCH(D35,'Tannbleking - Oppsalg US'!D:D, 0))), "Ja", "") | H35: Booket til time | I35: #1 | J35: Pasienten ringte inn slev og fikk time | L35: meta | M35: CV2015 | N35: 6843809575737 | O35: =TEXT(A35, "dd/mm/yyyy") -> 13/10/2025 | P35: =TO_UNIX_TIMESTAMP_DMY_HM(O35, B35) -> 1760357820 | T35: 4c641ac42c5e55ea43d8fa7184247d6f4c5173e040d9032e0a62beadba330dc8 | U35: 0ffa1ab66da3fc7744a772969760e476998a4af8a4fbaeec934b9781ed8cbed4 | V35: 2025-10-13T10:17:34+00:00 | X35: {post_referrer} | Y35: https://tannskjema.no | Z35: https://tannskjema.no/groruddalen-tannlegesenter | AC35: Facebook_Mobile_Reels
A36: 45943 | B36: 13:13 | C36: Shaiza Sakhi | D36: shaiza_sakhi91@hotmail.com | E36: 4748510226 | F36: 03.11.2025 | G36: =IF(NOT(ISERROR(MATCH(D36,'Tannbleking - Oppsalg US'!D:D, 0))), "Ja", "") | H36: Booket til time | I36: #2 | L36: meta | M36: CV2015 | N36: 6843809575737 | O36: =TEXT(A36, "dd/mm/yyyy") -> 13/10/2025 | P36: =TO_UNIX_TIMESTAMP_DMY_HM(O36, B36) -> 1760361180 | T36: 33feab9d73450db995481232d8d87112f1454ae1094d950fc930dffcadee4057 | U36: 70ecd6fa1c3b6ca7e45f66d8d2fd3fcea4625301470df6bfc462bc9369f51447 | V36: 2025-10-13T11:13:41+00:00 | X36: {post_referrer} | Y36: https://tannskjema.no | Z36: https://tannskjema.no/groruddalen-tannlegesenter | AC36: Facebook_Mobile_Feed
A37: 45943 | B37: 13:38 | C37: Josefina Claudio Solano | D37: josefina-solano@hotmail.com | E37: 4798448385 | F37: 14.10/2025 | G37: =IF(NOT(ISERROR(MATCH(D37,'Tannbleking - Oppsalg US'!D:D, 0))), "Ja", "") | H37: Ikke interessert | J37: Har vært hos tannlegen | L37: meta | M37: CV2010 | N37: 6843762966937 | O37: =TEXT(A37, "dd/mm/yyyy") -> 13/10/2025 | P37: =TO_UNIX_TIMESTAMP_DMY_HM(O37, B37) -> 1760362680 | T37: 3e9f39b15150d71f0ca07ef0671ea78d325467a788d9e6d8f291fb7018c8a8bc | U37: 614d6ba320f70614db6cdd9180c74173e7d6c7b0c7d910607eb0cc5d1a36c653 | V37: 2025-10-13T11:38:18+00:00 | X37: {post_referrer} | Y37: https://tannskjema.no | Z37: https://tannskjema.no/groruddalen-tannlegesenter | AC37: Facebook_Mobile_Feed
A38: 45944 | B38: 09:59 | C38: Magnus Hansten | D38: hansten07@gmail.com | E38: 4748249819 | F38: lørdag, 18 oktober | G38: =IF(NOT(ISERROR(MATCH(D38,'Tannbleking - Oppsalg US'!D:D, 0))), "Ja", "") | H38: Booket til time | I38: #1 | L38: meta | M38: CV2015 | N38: 6843809575737 | O38: =TEXT(A38, "dd/mm/yyyy") -> 14/10/2025 | P38: =TO_UNIX_TIMESTAMP_DMY_HM(O38, B38) -> 1760435940 | T38: a1f33c014a6ea489030940f26c3b4b6ffbd9245ecd0c780b579ddba9edc4e095 | U38: 1419e344d1d0b42a31a49779601df15c6646e0dc640f8b7179acd8042a4b7014 | V38: 2025-10-14T07:59:10+00:00 | X38: {post_referrer} | Y38: https://tannskjema.no | Z38: https://tannskjema.no/groruddalen-tannlegesenter | AC38: Facebook_Stories
A39: 45944 | B39: 12:40 | C39: Andrea Holtekjølen | D39: andreaholte@hotmail.no | E39: 4795478202 | F39: 28.10.25 | G39: =IF(NOT(ISERROR(MATCH(D39,'Tannbleking - Oppsalg US'!D:D, 0))), "Ja", "") | H39: Booket til time | I39: #1 | L39: meta | M39: CV2010 | N39: 6843762966937 | O39: =TEXT(A39, "dd/mm/yyyy") -> 14/10/2025 | P39: =TO_UNIX_TIMESTAMP_DMY_HM(O39, B39) -> 1760445600 | T39: c5784ed2300d32ccf243cdd431c61110a5870b3572451a631a7d8e37733cc912 | U39: e826f85cc4f6f65436e9bee2c09c35795a651de96e6f7e6cf8ed001b346606e3 | V39: 2025-10-14T10:40:03+00:00 | X39: {post_referrer} | Y39: https://tannskjema.no | Z39: https://tannskjema.no/groruddalen-tannlegesenter | AC39: Facebook_Desktop_Feed
A40: 45944 | B40: 12:49 | C40: Irene Håheim | D40: irenehaheim@hotmail.com | E40: 4790973645 | F40: 30. oktober | G40: =IF(NOT(ISERROR(MATCH(D40,'Tannbleking - Oppsalg US'!D:D, 0))), "Ja", "") | H40: Booket til time | I40: #1 | L40: meta | M40: CV2010 | N40: 6843762966937 | O40: =TEXT(A40, "dd/mm/yyyy") -> 14/10/2025 | P40: =TO_UNIX_TIMESTAMP_DMY_HM(O40, B40) -> 1760446140 | T40: 1be1ac47f995292cf3ddc275d6fd85a0550fa9f0989c3c023fe9eea3db5ef720 | U40: 0727bcee74beac6e37e878962b59b7c33524e825b87a05628764831e2de5d0a1 | V40: 2025-10-14T10:49:37+00:00 | X40: {post_referrer} | Y40: https://tannskjema.no | Z40: https://tannskjema.no/groruddalen-tannlegesenter | AC40: Facebook_Mobile_Feed
...

Sheet Tannbleking - Oppsalg US
A1: Dato | B1: Tidspunkt | C1: Navn | D1: E-post | E1: Telefon | F1: Kommentar
A2: 45407 | B2: 14:57 | C2: Vetle Robstad | D2: vetle.robstad85@gmail.com | E2: 97974145
A3: 45930 | B3: 11:23 | C3: Ole Tom Pettersen | D3: oletompettersen@gmail.com | E3: 4797467341
A4: 45930 | B4: 11:25 | C4: Ole Tom Pettersen | D4: oletompettersen@gmail.com | E4: 4797467341
A5: 45930 | B5: 11:25 | C5: Ole Tom Pettersen | D5: oletompettersen@gmail.com | E5: 4797467341
A6: 45931 | B6: 05:47 | C6: Zere Abraha Hiyabu | D6: zhiyabu@gmail.com | E6: 48354835
A7: 45931 | B7: 06:26 | C7: Malyun Mume | D7: saboontu88@hotmail.com | E7: 47467165
A8: 45940 | B8: 12:40 | C8: Tine Pedersen | D8: tinep86@hotmail.com | E8: 93680400
A9: 45952 | B9: 14:30 | C9: Rose Larsen | D9: njokurecha@yahoo.no | E9: 97692210
A10: 45956 | B10: 07:08 | C10: Simon Solheim | D10: sfsolheim@gmail.com | E10: 98604319
A11: 45956 | B11: 08:31 | C11: Janusz | D11: januszmilosek@gmail.com | E11: 96837894
A12: 45969 | B12: 00:08 | C12: Emirhan Nedzhib | D12: emirhandemirel585@gmail.com | E12: 4792530934
A13: 45987 | B13: 22:55 | C13: Rajshekhar Bhattacharya | D13: r277735@gmail.com | E13: 4791278340
... A34: 46151 | B34: 08:33 | C34: Mabel Akogyeram | D34: mabel.akogyeram@gmail.com | E34: 4790983320

Sheet Totalt US 2026
B2: 2026 Kampanjeresultater - US 590 kr
B4: Kostnad per henvendelse | D4: Antall henvendelser | F4: Bookingsrate US
B5: =$U$30 -> 0 | D5: =$S$30 -> 19 | F5: =$Z$30 -> 0.68421053
B7: Kostnad per pasient | D7: Antall nye pasienter | F7: Omsetning fra US
B8: =$V$30 -> 0 | D8: =$T$30 -> 13 | F8: =$AA$30 -> 7670
B10: Beløp brukt | D10: Omsetning fra kampanje | F10: Omsetning fra oppsalg
B11: =$R$30 -> 0 | D11: =$X$30 -> 15140 | F11: =$AC$30 -> 7470
F12: =$AD$30 -> 0.15789474
B13: Annonseavkastning | D13: Potensiell omsetning 2000 kr | F13: Antall oppsalg
B14: =$W$30 -> #DIV/0! | D14: =$Y$30 -> 33470 | F14: =$AB$30 -> 3
Q17: Måned | R17: Beløp brukt | S17: Antall henvendelser | T17: Antall pasienter | U17: Kostnad per henvendelse | V17: Kostnad per pasient | W17: ROAS | X17: Omsetning fra kampanje | Y17: Potensiell omsetning | Z17: US Bookingrate | AA17: Omsetning fra US | AB17: Antall oppsalg | AC17: Omsetning fra oppsalg | AD17: CVR Upsale | AE17: Meta Link Clicks | AF17: CVR Exam
Q18: Januar | R18: =R45+R61 -> 0 | S18: =COUNTIFS(US!$A:$A, ">=" & DATE(2026,1,1), US!$A:$A, "<=" & EOMONTH(DATE(2026,1,1), 0)) -> 0 | T18: =COUNTIFS(US!$A:$A, ">=" & DATE(2026,1,1), US!$A:$A, "<=" & EOMONTH(DATE(2026,1,1), 0), US!$H:$H, "Booket til time") -> 0 | U18: =R18/S18 -> #DIV/0! | V18: =R18/T18 -> #DIV/0! | W18: =Y18/R18 -> #DIV/0! | X18: =($S$32*T18)+AC18 -> 0 | Y18: =($S$33*T18)+AC18 -> 0 | Z18: =T18/S18 -> #DIV/0! | AA18: =T18*$S$32 -> 0 | AB18: =COUNTIFS(US!$A:$A, ">=" & DATE(2026,1,1), US!$A:$A, "<=" & EOMONTH(DATE(2026,1,1), 0), US!$G:$G, "Ja") -> 0 | AC18: =AB18*$S$34 -> 0 | AD18: =AB18/S18 -> #DIV/0! | AF18: =S18/AE18 -> #DIV/0!
Q19: Februar | R19: =R46+R62 -> 0 | S19: =COUNTIFS(US!$A:$A, ">=" & DATE(2026,2,1), US!$A:$A, "<=" & EOMONTH(DATE(2026,2,1), 0)) -> 0 | T19: =COUNTIFS(US!$A:$A, ">=" & DATE(2026,2,1), US!$A:$A, "<=" & EOMONTH(DATE(2026,2,1), 0), US!$H:$H, "Booket til time") -> 0 | U19: =R19/S19 -> #DIV/0! | V19: =R19/T19 -> #DIV/0! | W19: =Y19/R19 -> #DIV/0! | X19: =($S$32*T19)+AC19 -> 0 | Y19: =($S$33*T19)+AC19 -> 0 | Z19: =T19/S19 -> #DIV/0! | AA19: =T19*$S$32 -> 0 | AB19: =COUNTIFS(US!$A:$A, ">=" & DATE(2026,2,1), US!$A:$A, "<=" & EOMONTH(DATE(2026,2,1), 0), US!$G:$G, "Ja") -> 0 | AC19: =AB19*$S$34 -> 0 | AD19: =AB19/S19 -> #DIV/0! | AF19: =S19/AE19 -> #DIV/0!
Q20: Mars | R20: =R47+R63 -> 0 | S20: =COUNTIFS(US!$A:$A, ">=" & DATE(2026,3,1), US!$A:$A, "<=" & EOMONTH(DATE(2026,3,1), 0)) -> 0 | T20: =COUNTIFS(US!$A:$A, ">=" & DATE(2026,3,1), US!$A:$A, "<=" & EOMONTH(DATE(2026,3,1), 0), US!$H:$H, "Booket til time") -> 0 | U20: =R20/S20 -> #DIV/0! | V20: =R20/T20 -> #DIV/0! | W20: =Y20/R20 -> #DIV/0! | X20: =($S$32*T20)+AC20 -> 0 | Y20: =($S$33*T20)+AC20 -> 0 | Z20: =T20/S20 -> #DIV/0! | AA20: =T20*$S$32 -> 0 | AB20: =COUNTIFS(US!$A:$A, ">=" & DATE(2026,3,1), US!$A:$A, "<=" & EOMONTH(DATE(2026,3,1), 0), US!$G:$G, "Ja") -> 0 | AC20: =AB20*$S$34 -> 0 | AD20: =AB20/S20 -> #DIV/0! | AF20: =S20/AE20 -> #DIV/0!
Q21: April | R21: =R48+R64 -> 0 | S21: =COUNTIFS(US!$A:$A, ">=" & DATE(2026,4,1), US!$A:$A, "<=" & EOMONTH(DATE(2026,4,1), 0)) -> 0 | T21: =COUNTIFS(US!$A:$A, ">=" & DATE(2026,4,1), US!$A:$A, "<=" & EOMONTH(DATE(2026,4,1), 0), US!$H:$H, "Booket til time") -> 0 | U21: =R21/S21 -> #DIV/0! | V21: =R21/T21 -> #DIV/0! | W21: =Y21/R21 -> #DIV/0! | X21: =($S$32*T21)+AC21 -> 0 | Y21: =($S$33*T21)+AC21 -> 0 | Z21: =T21/S21 -> #DIV/0! | AA21: =T21*$S$32 -> 0 | AB21: =COUNTIFS(US!$A:$A, ">=" & DATE(2026,4,1), US!$A:$A, "<=" & EOMONTH(DATE(2026,4,1), 0), US!$G:$G, "Ja") -> 0 | AC21: =AB21*$S$34 -> 0 | AD21: =AB21/S21 -> #DIV/0! | AF21: =S21/AE21 -> #DIV/0!
Q22: Mai | R22: =R49+R65 -> 0 | S22: =COUNTIFS(US!$A:$A, ">=" & DATE(2026,5,1), US!$A:$A, "<=" & EOMONTH(DATE(2026,5,1), 0)) -> 0 | T22: =COUNTIFS(US!$A:$A, ">=" & DATE(2026,5,1), US!$A:$A, "<=" & EOMONTH(DATE(2026,5,1), 0), US!$H:$H, "Booket til time") -> 0 | U22: =R22/S22 -> #DIV/0! | V22: =R22/T22 -> #DIV/0! | W22: =Y22/R22 -> #DIV/0! | X22: =($S$32*T22)+AC22 -> 0 | Y22: =($S$33*T22)+AC22 -> 0 | Z22: =T22/S22 -> #DIV/0! | AA22: =T22*$S$32 -> 0 | AB22: =COUNTIFS(US!$A:$A, ">=" & DATE(2026,5,1), US!$A:$A, "<=" & EOMONTH(DATE(2026,5,1), 0), US!$G:$G, "Ja") -> 0 | AC22: =AB22*$S$34 -> 0 | AD22: =AB22/S22 -> #DIV/0! | AF22: =S22/AE22 -> #DIV/0!
Q23: Juni | R23: =R50+R66 -> 0 | S23: =COUNTIFS(US!$A:$A, ">=" & DATE(2026,6,1), US!$A:$A, "<=" & EOMONTH(DATE(2026,6,1), 0)) -> 0 | T23: =COUNTIFS(US!$A:$A, ">=" & DATE(2026,6,1), US!$A:$A, "<=" & EOMONTH(DATE(2026,6,1), 0), US!$H:$H, "Booket til time") -> 0 | U23: =R23/S23 -> #DIV/0! | V23: =R23/T23 -> #DIV/0! | W23: =Y23/R23 -> #DIV/0! | X23: =($S$32*T23)+AC23 -> 0 | Y23: =($S$33*T23)+AC23 -> 0 | Z23: =T23/S23 -> #DIV/0! | AA23: =T23*$S$32 -> 0 | AB23: =COUNTIFS(US!$A:$A, ">=" & DATE(2026,6,1), US!$A:$A, "<=" & EOMONTH(DATE(2026,6,1), 0), US!$G:$G, "Ja") -> 0 | AC23: =AB23*$S$34 -> 0 | AD23: =AB23/S23 -> #DIV/0! | AF23: =S23/AE23 -> #DIV/0!
Q24: Juli | R24: =R51+R67 -> 0 | S24: =COUNTIFS(US!$A:$A, ">=" & DATE(2026,7,1), US!$A:$A, "<=" & EOMONTH(DATE(2026,7,1), 0)) -> 19 | T24: =COUNTIFS(US!$A:$A, ">=" & DATE(2026,7,1), US!$A:$A, "<=" & EOMONTH(DATE(2026,7,1), 0), US!$H:$H, "Booket til time") -> 13 | U24: =R24/S24 -> 0 | V24: =R24/T24 -> 0 | W24: =Y24/R24 -> #DIV/0! | X24: =($S$32*T24)+AC24 -> 15140 | Y24: =($S$33*T24)+AC24 -> 33470 | Z24: =T24/S24 -> 0.68421053 | AA24: =T24*$S$32 -> 7670 | AB24: =COUNTIFS(US!$A:$A, ">=" & DATE(2026,7,1), US!$A:$A, "<=" & EOMONTH(DATE(2026,7,1), 0), US!$G:$G, "Ja") -> 3 | AC24: =AB24*$S$34 -> 7470 | AD24: =AB24/S24 -> 0.15789474 | AF24: =S24/AE24 -> #DIV/0!
Q25: August | R25: =R52+R68 -> 0 | S25: =COUNTIFS(US!$A:$A, ">=" & DATE(2026,8,1), US!$A:$A, "<=" & EOMONTH(DATE(2026,8,1), 0)) -> 0 | T25: =COUNTIFS(US!$A:$A, ">=" & DATE(2026,8,1), US!$A:$A, "<=" & EOMONTH(DATE(2026,8,1), 0), US!$H:$H, "Booket til time") -> 0 | U25: =R25/S25 -> #DIV/0! | V25: =R25/T25 -> #DIV/0! | W25: =Y25/R25 -> #DIV/0! | X25: =($S$32*T25)+AC25 -> 0 | Y25: =($S$33*T25)+AC25 -> 0 | Z25: =T25/S25 -> #DIV/0! | AA25: =T25*$S$32 -> 0 | AB25: =COUNTIFS(US!$A:$A, ">=" & DATE(2026,8,1), US!$A:$A, "<=" & EOMONTH(DATE(2026,8,1), 0), US!$G:$G, "Ja") -> 0 | AC25: =AB25*$S$34 -> 0 | AD25: =AB25/S25 -> #DIV/0! | AF25: =S25/AE25 -> #DIV/0!
Q26: September | R26: =R53+R69 -> 0 | S26: =COUNTIFS(US!$A:$A, ">=" & DATE(2026,9,1), US!$A:$A, "<=" & EOMONTH(DATE(2026,9,1), 0)) -> 0 | T26: =COUNTIFS(US!$A:$A, ">=" & DATE(2026,9,1), US!$A:$A, "<=" & EOMONTH(DATE(2026,9,1), 0), US!$H:$H, "Booket til time") -> 0 | U26: =R26/S26 -> #DIV/0! | V26: =R26/T26 -> #DIV/0! | W26: =Y26/R26 -> #DIV/0! | X26: =($S$32*T26)+AC26 -> 0 | Y26: =($S$33*T26)+AC26 -> 0 | Z26: =T26/S26 -> #DIV/0! | AA26: =T26*$S$32 -> 0 | AB26: =COUNTIFS(US!$A:$A, ">=" & DATE(2026,9,1), US!$A:$A, "<=" & EOMONTH(DATE(2026,9,1), 0), US!$G:$G, "Ja") -> 0 | AC26: =AB26*$S$34 -> 0 | AD26: =AB26/S26 -> #DIV/0! | AF26: =S26/AE26 -> #DIV/0!
Q27: Oktober | R27: =R54+R70 -> 0 | S27: =COUNTIFS(US!$A:$A, ">=" & DATE(2026,10,1), US!$A:$A, "<=" & EOMONTH(DATE(2026,10,1), 0)) -> 0 | T27: =COUNTIFS(US!$A:$A, ">=" & DATE(2026,10,1), US!$A:$A, "<=" & EOMONTH(DATE(2026,10,1), 0), US!$H:$H, "Booket til time") -> 0 | U27: =R27/S27 -> #DIV/0! | V27: =R27/T27 -> #DIV/0! | W27: =Y27/R27 -> #DIV/0! | X27: =($S$32*T27)+AC27 -> 0 | Y27: =($S$33*T27)+AC27 -> 0 | Z27: =T27/S27 -> #DIV/0! | AA27: =T27*$S$32 -> 0 | AB27: =COUNTIFS(US!$A:$A, ">=" & DATE(2026,10,1), US!$A:$A, "<=" & EOMONTH(DATE(2026,10,1), 0), US!$G:$G, "Ja") -> 0 | AC27: =AB27*$S$34 -> 0 | AD27: =AB27/S27 -> #DIV/0! | AF27: =S27/AE27 -> #DIV/0!
Q28: November | R28: =R55+R71 -> 0 | S28: =COUNTIFS(US!$A:$A, ">=" & DATE(2026,11,1), US!$A:$A, "<=" & EOMONTH(DATE(2026,11,1), 0)) -> 0 | T28: =COUNTIFS(US!$A:$A, ">=" & DATE(2026,11,1), US!$A:$A, "<=" & EOMONTH(DATE(2026,11,1), 0), US!$H:$H, "Booket til time") -> 0 | U28: =R28/S28 -> #DIV/0! | V28: =R28/T28 -> #DIV/0! | W28: =Y28/R28 -> #DIV/0! | X28: =($S$32*T28)+AC28 -> 0 | Y28: =($S$33*T28)+AC28 -> 0 | Z28: =T28/S28 -> #DIV/0! | AA28: =T28*$S$32 -> 0 | AB28: =COUNTIFS(US!$A:$A, ">=" & DATE(2026,11,1), US!$A:$A, "<=" & EOMONTH(DATE(2026,11,1), 0), US!$G:$G, "Ja") -> 0 | AC28: =AB28*$S$34 -> 0 | AD28: =AB28/S28 -> #DIV/0! | AF28: =S28/AE28 -> #DIV/0!
Q29: Desember | R29: =R56+R72 -> 0 | S29: =COUNTIFS(US!$A:$A, ">=" & DATE(2026,12,1), US!$A:$A, "<=" & EOMONTH(DATE(2026,12,1), 0)) -> 0 | T29: =COUNTIFS(US!$A:$A, ">=" & DATE(2026,12,1), US!$A:$A, "<=" & EOMONTH(DATE(2026,12,1), 0), US!$H:$H, "Booket til time") -> 0 | U29: =R29/S29 -> #DIV/0! | V29: =R29/T29 -> #DIV/0! | W29: =Y29/R29 -> #DIV/0! | X29: =($S$32*T29)+AC29 -> 0 | Y29: =($S$33*T29)+AC29 -> 0 | Z29: =T29/S29 -> #DIV/0! | AA29: =T29*$S$32 -> 0 | AB29: =COUNTIFS(US!$A:$A, ">=" & DATE(2026,12,1), US!$A:$A, "<=" & EOMONTH(DATE(2026,12,1), 0), US!$G:$G, "Ja") -> 0 | AC29: =AB29*$S$34 -> 0 | AD29: =AB29/S29 -> #DIV/0! | AF29: =S29/AE29 -> #DIV/0!
Q30: Totalt | R30: =SUM(R18:R29) -> 0 | S30: =SUM(S18:S29) -> 19 | T30: =SUM(T18:T29) -> 13 | U30: =R30/S30 -> 0 | V30: =R30/T30 -> 0 | W30: =Y30/R30 -> #DIV/0! | X30: =SUM(X18:X29) -> 15140 | Y30: =SUM(Y18:Y29) -> 33470 | Z30: =T30/S30 -> 0.68421053 | AA30: =SUM(AA18:AA29) -> 7670 | AB30: =SUM(AB18:AB29) -> 3 | AC30: =SUM(AC18:AC29) -> 7470 | AD30: =AB30/S30 -> 0.15789474 | AE30: =SUM(AE18:AE29) -> 0 | AF30: =S30/AE30 -> #DIV/0!
Q32: Omsetning | S32: 590 | U32: URL
Q33: Potensiell omsetning | S33: 2000 | U33: {=UNIQUE(US!Z:Z)} -> post url
Q34: Oppsalg tannbleking | S34: 2490 | X34: =COUNTIF(US!Z:Z,U34) -> 0
Q35: US Leads yesterday | S35: =COUNTIF(US!$A:$A, TODAY()-1) -> 0 | X35: =COUNTIF(US!Z:Z,U35) -> 0
Q36: US Leads today | S36: =COUNTIF(US!$A:$A, TODAY()) -> 0 | X36: =SUM(X34:X35) -> 0
Q37: US Leads this month | S37: =COUNTIFS(US!$A:$A, ">=" & EOMONTH(TODAY(), -1) + 1, US!$A:$A, "<=" & EOMONTH(TODAY(), 0)) -> 19
Q43: META
Q44: Måned | R44: Beløp brukt | S44: Antall henvendelser | T44: Antall pasienter | U44: Kostnad per henvendelse | V44: Kostnad per pasient | W44: ROAS | X44: Omsetning fra kampanje | Y44: Potensiell omsetning | Z44: US Bookingrate | AA44: Omsetning fra US | AB44: Antall oppsalg | AC44: Omsetning fra oppsalg | AD44: CVR Upsale | AE44: Meta Link Clicks | AF44: CVR Exam
Q45: Januar | R45: 0 | S45: =COUNTIFS(US!$A:$A, ">=" & DATE(YEAR(TODAY()),1,1), US!$A:$A, "<=" & EOMONTH(DATE(YEAR(TODAY()),1,1), 0)) -> 0 | T45: =COUNTIFS(US!$A:$A, ">=" & DATE(YEAR(TODAY()),1,1), US!$A:$A, "<=" & EOMONTH(DATE(YEAR(TODAY()),1,1), 0), US!$H:$H, "Booket til time") -> 0 | U45: =R45/S45 -> #DIV/0! | V45: =R45/T45 -> #DIV/0! | W45: =$B$88 -> #DIV/0! | X45: =($S$32*T45)+AC45 -> 0 | Y45: =($S$33*T45)+AC45 -> 0 | Z45: =$F$79 -> #DIV/0! | AA45: =T45*$S$32 -> 0 | AB45: =COUNTIFS(US!$A:$A, ">=" & DATE(YEAR(TODAY()),1,1), US!$A:$A, "<=" & EOMONTH(DATE(YEAR(TODAY()),1,1), 0), US!$G:$G, "Ja") -> 0 | AC45: =AB45*$S$34 -> 0 | AD45: =F115/D106 -> #DIV/0! | AE45: 0 | AF45: =S45/AE45 -> #DIV/0!
Q46: Februar | R46: 0 | S46: =COUNTIFS(US!$A:$A, ">=" & DATE(YEAR(TODAY()),2,1), US!$A:$A, "<=" & EOMONTH(DATE(YEAR(TODAY()),2,1), 0)) -> 0 | T46: =COUNTIFS(US!$A:$A, ">=" & DATE(YEAR(TODAY()),2,1), US!$A:$A, "<=" & EOMONTH(DATE(YEAR(TODAY()),2,1), 0), US!$H:$H, "Booket til time") -> 0 | U46: =R46/S46 -> #DIV/0! | V46: =R46/T46 -> #DIV/0! | W46: =$H$88 -> #DIV/0! | X46: =($S$32*T46)+AC46 -> 0 | Y46: =($S$33*T46)+AC46 -> 0 | Z46: =$L$79 -> #DIV/0! | AA46: =T46*$S$32 -> 0 | AB46: =COUNTIFS(US!$A:$A, ">=" & DATE(YEAR(TODAY()),2,1), US!$A:$A, "<=" & EOMONTH(DATE(YEAR(TODAY()),2,1), 0), US!$G:$G, "Ja") -> 0 | AC46: =AB46*$S$34 -> 0 | AD46: =L115/J106 -> #DIV/0! | AE46: 0 | AF46: =S46/AE46 -> #DIV/0!
Q47: Mars | R47: 0 | S47: =COUNTIFS(US!$A:$A, ">=" & DATE(YEAR(TODAY()),3,1), US!$A:$A, "<=" & EOMONTH(DATE(YEAR(TODAY()),3,1), 0)) -> 0 | T47: =COUNTIFS(US!$A:$A, ">=" & DATE(YEAR(TODAY()),3,1), US!$A:$A, "<=" & EOMONTH(DATE(YEAR(TODAY()),3,1), 0), US!$H:$H, "Booket til time") -> 0 | U47: =R47/S47 -> #DIV/0! | V47: =R47/T47 -> #DIV/0! | W47: =$B$104 -> #DIV/0! | X47: =($S$32*T47)+AC47 -> 0 | Y47: =($S$33*T47)+AC47 -> 0 | Z47: =$F$95 -> #DIV/0! | AA47: =T47*$S$32 -> 0 | AB47: =COUNTIFS(US!$A:$A, ">=" & DATE(YEAR(TODAY()),3,1), US!$A:$A, "<=" & EOMONTH(DATE(YEAR(TODAY()),3,1), 0), US!$G:$G, "Ja") -> 0 | AC47: =AB47*$S$34 -> 0 | AD47: =L116/J107 -> #VALUE! | AE47: 125 | AF47: =S47/AE47 -> 0
Q48: April | R48: 0 | S48: =COUNTIFS(US!$A:$A, ">=" & DATE(YEAR(TODAY()),4,1), US!$A:$A, "<=" & EOMONTH(DATE(YEAR(TODAY()),4,1), 0)) -> 0 | T48: =COUNTIFS(US!$A:$A, ">=" & DATE(YEAR(TODAY()),4,1), US!$A:$A, "<=" & EOMONTH(DATE(YEAR(TODAY()),4,1), 0), US!$H:$H, "Booket til time") -> 0 | U48: =R48/S48 -> #DIV/0! | V48: =R48/T48 -> #DIV/0! | W48: =$H$104 -> #DIV/0! | X48: =($S$32*T48)+AC48 -> 0 | Y48: =($S$33*T48)+AC48 -> 0 | Z48: =$L$95 -> #DIV/0! | AA48: =T48*$S$32 -> 0 | AB48: =COUNTIFS(US!$A:$A, ">=" & DATE(YEAR(TODAY()),4,1), US!$A:$A, "<=" & EOMONTH(DATE(YEAR(TODAY()),4,1), 0), US!$G:$G, "Ja") -> 0 | AC48: =AB48*$S$34 -> 0 | AD48: =AB48/S48 -> #DIV/0! | AF48: =S48/AE48 -> #DIV/0!
Q49: Mai | R49: 0 | S49: =COUNTIFS(US!$A:$A, ">=" & DATE(YEAR(TODAY()),5,1), US!$A:$A, "<=" & EOMONTH(DATE(YEAR(TODAY()),5,1), 0)) -> 0 | T49: =COUNTIFS(US!$A:$A, ">=" & DATE(YEAR(TODAY()),5,1), US!$A:$A, "<=" & EOMONTH(DATE(YEAR(TODAY()),5,1), 0), US!$H:$H, "Booket til time") -> 0 | U49: =R49/S49 -> #DIV/0! | V49: =R49/T49 -> #DIV/0! | W49: =$B$120 -> #DIV/0! | X49: =($S$32*T49)+AC49 -> 0 | Y49: =($S$33*T49)+AC49 -> 0 | Z49: =$F$111 -> #DIV/0! | AA49: =T49*$S$32 -> 0 | AB49: =COUNTIFS(US!$A:$A, ">=" & DATE(YEAR(TODAY()),5,1), US!$A:$A, "<=" & EOMONTH(DATE(YEAR(TODAY()),5,1), 0), US!$G:$G, "Ja") -> 0 | AC49: =AB49*$S$34 -> 0 | AD49: =AB49/S49 -> #DIV/0! | AF49: =S49/AE49 -> #DIV/0!
Q50: Juni | R50: 0 | S50: =COUNTIFS(US!$A:$A, ">=" & DATE(YEAR(TODAY()),6,1), US!$A:$A, "<=" & EOMONTH(DATE(YEAR(TODAY()),6,1), 0)) -> 0 | T50: =COUNTIFS(US!$A:$A, ">=" & DATE(YEAR(TODAY()),6,1), US!$A:$A, "<=" & EOMONTH(DATE(YEAR(TODAY()),6,1), 0), US!$H:$H, "Booket til time") -> 0 | U50: =R50/S50 -> #DIV/0! | V50: =R50/T50 -> #DIV/0! | W50: =$H$120 -> #DIV/0! | X50: =($S$32*T50)+AC50 -> 0 | Y50: =($S$33*T50)+AC50 -> 0 | Z50: =$L$111 -> #DIV/0! | AA50: =T50*$S$32 -> 0 | AB50: =COUNTIFS(US!$A:$A, ">=" & DATE(YEAR(TODAY()),6,1), US!$A:$A, "<=" & EOMONTH(DATE(YEAR(TODAY()),6,1), 0), US!$G:$G, "Ja") -> 0 | AC50: =AB50*$S$34 -> 0 | AD50: =AB50/S50 -> #DIV/0! | AF50: =S50/AE50 -> #DIV/0!
Q51: Juli | R51: 0 | S51: =COUNTIFS(US!$A:$A, ">=" & DATE(YEAR(TODAY()),7,1), US!$A:$A, "<=" & EOMONTH(DATE(YEAR(TODAY()),7,1), 0)) -> 19 | T51: =COUNTIFS(US!$A:$A, ">=" & DATE(YEAR(TODAY()),7,1), US!$A:$A, "<=" & EOMONTH(DATE(YEAR(TODAY()),7,1), 0), US!$H:$H, "Booket til time") -> 13 | U51: =R51/S51 -> 0 | V51: =R51/T51 -> 0 | W51: =$B$136 -> #DIV/0! | X51: =($S$32*T51)+AC51 -> 15140 | Y51: =($S$33*T51)+AC51 -> 33470 | Z51: =$F$127 -> 0.68421053 | AA51: =T51*$S$32 -> 7670 | AB51: =COUNTIFS(US!$A:$A, ">=" & DATE(YEAR(TODAY()),7,1), US!$A:$A, "<=" & EOMONTH(DATE(YEAR(TODAY()),7,1), 0), US!$G:$G, "Ja") -> 3 | AC51: =AB51*$S$34 -> 7470 | AD51: =AB51/S51 -> 0.15789474 | AF51: =S51/AE51 -> #DIV/0!
Q52: August | R52: 0 | S52: =COUNTIFS(US!$A:$A, ">=" & DATE(YEAR(TODAY()),8,1), US!$A:$A, "<=" & EOMONTH(DATE(YEAR(TODAY()),8,1), 0)) -> 0 | T52: =COUNTIFS(US!$A:$A, ">=" & DATE(YEAR(TODAY()),8,1), US!$A:$A, "<=" & EOMONTH(DATE(YEAR(TODAY()),8,1), 0), US!$H:$H, "Booket til time") -> 0 | U52: =R52/S52 -> #DIV/0! | V52: =R52/T52 -> #DIV/0! | W52: =$H$136 -> #DIV/0! | X52: =($S$32*T52)+AC52 -> 0 | Y52: =($S$33*T52)+AC52 -> 0 | Z52: =$L$127 -> #DIV/0! | AA52: =T52*$S$32 -> 0 | AB52: =COUNTIFS(US!$A:$A, ">=" & DATE(YEAR(TODAY()),8,1), US!$A:$A, "<=" & EOMONTH(DATE(YEAR(TODAY()),8,1), 0), US!$G:$G, "Ja") -> 0 | AC52: =AB52*$S$34 -> 0 | AD52: =AB52/S52 -> #DIV/0! | AF52: =S52/AE52 -> #DIV/0!
...

Sheet Totalt US 2025
B2: 2025 Kampanjeresultater - US 590 kr
B4: Kostnad per henvendelse | D4: Antall henvendelser | F4: Bookingsrate US
B5: =$U$30 -> #DIV/0! | D5: =$S$30 -> 0 | F5: =$Z$30 -> #DIV/0!
B7: Kostnad per pasient | D7: Antall nye pasienter | F7: Omsetning fra US
B8: =$V$30 -> #DIV/0! | D8: =$T$30 -> 0 | F8: =$AA$30 -> 0
B10: Beløp brukt | D10: Omsetning fra kampanje | F10: Omsetning fra oppsalg
B11: =$R$30 -> 6022 | D11: =$X$30 -> 0 | F11: =$AC$30 -> 0
F12: =$AD$30 -> #DIV/0!
B13: Annonseavkastning | D13: Potensiell omsetning 2000 kr | F13: Antall oppsalg
B14: =$W$30 -> 0 | D14: =$Y$30 -> 0 | F14: =$AB$30 -> 0
Q17: Måned | R17: Beløp brukt | S17: Antall henvendelser | T17: Antall pasienter | U17: Kostnad per henvendelse | V17: Kostnad per pasient | W17: ROAS | X17: Omsetning fra kampanje | Y17: Potensiell omsetning | Z17: US Bookingrate | AA17: Omsetning fra US | AB17: Antall oppsalg | AC17: Omsetning fra oppsalg | AD17: CVR Upsale | AE17: Meta Link Clicks | AF17: CVR Exam
Q18: Januar | R18: =R45+R61 -> 0 | S18: =COUNTIFS(US!$A:$A, ">=" & DATE(2025,1,1), US!$A:$A, "<=" & EOMONTH(DATE(2025,1,1), 0)) -> 0 | T18: =COUNTIFS(US!$A:$A, ">=" & DATE(2025,1,1), US!$A:$A, "<=" & EOMONTH(DATE(2025,1,1), 0), US!$H:$H, "Booket til time") -> 0 | U18: =R18/S18 -> #DIV/0! | V18: =R18/T18 -> #DIV/0! | W18: =Y18/R18 -> #DIV/0! | X18: =($S$32*T18)+AC18 -> 0 | Y18: =($S$33*T18)+AC18 -> 0 | Z18: =T18/S18 -> #DIV/0! | AA18: =T18*$S$32 -> 0 | AB18: =COUNTIFS(US!$A:$A, ">=" & DATE(2025,1,1), US!$A:$A, "<=" & EOMONTH(DATE(2025,1,1), 0), US!$G:$G, "Ja") -> 0 | AC18: =AB18*$S$34 -> 0 | AD18: =AB18/S18 -> #DIV/0! | AF18: =S18/AE18 -> #DIV/0!
Q19: Februar | R19: =R46+R62 -> 0 | S19: =COUNTIFS(US!$A:$A, ">=" & DATE(2025,2,1), US!$A:$A, "<=" & EOMONTH(DATE(2025,2,1), 0)) -> 0 | T19: =COUNTIFS(US!$A:$A, ">=" & DATE(2025,2,1), US!$A:$A, "<=" & EOMONTH(DATE(2025,2,1), 0), US!$H:$H, "Booket til time") -> 0 | U19: =R19/S19 -> #DIV/0! | V19: =R19/T19 -> #DIV/0! | W19: =Y19/R19 -> #DIV/0! | X19: =($S$32*T19)+AC19 -> 0 | Y19: =($S$33*T19)+AC19 -> 0 | Z19: =T19/S19 -> #DIV/0! | AA19: =T19*$S$32 -> 0 | AB19: =COUNTIFS(US!$A:$A, ">=" & DATE(2025,2,1), US!$A:$A, "<=" & EOMONTH(DATE(2025,2,1), 0), US!$G:$G, "Ja") -> 0 | AC19: =AB19*$S$34 -> 0 | AD19: =AB19/S19 -> #DIV/0! | AF19: =S19/AE19 -> #DIV/0!
Q20: Mars | R20: =R47+R63 -> 0 | S20: =COUNTIFS(US!$A:$A, ">=" & DATE(2025,3,1), US!$A:$A, "<=" & EOMONTH(DATE(2025,3,1), 0)) -> 0 | T20: =COUNTIFS(US!$A:$A, ">=" & DATE(2025,3,1), US!$A:$A, "<=" & EOMONTH(DATE(2025,3,1), 0), US!$H:$H, "Booket til time") -> 0 | U20: =R20/S20 -> #DIV/0! | V20: =R20/T20 -> #DIV/0! | W20: =Y20/R20 -> #DIV/0! | X20: =($S$32*T20)+AC20 -> 0 | Y20: =($S$33*T20)+AC20 -> 0 | Z20: =T20/S20 -> #DIV/0! | AA20: =T20*$S$32 -> 0 | AB20: =COUNTIFS(US!$A:$A, ">=" & DATE(2025,3,1), US!$A:$A, "<=" & EOMONTH(DATE(2025,3,1), 0), US!$G:$G, "Ja") -> 0 | AC20: =AB20*$S$34 -> 0 | AD20: =AB20/S20 -> #DIV/0! | AF20: =S20/AE20 -> #DIV/0!
Q21: April | R21: =R48+R64 -> 0 | S21: =COUNTIFS(US!$A:$A, ">=" & DATE(2025,4,1), US!$A:$A, "<=" & EOMONTH(DATE(2025,4,1), 0)) -> 0 | T21: =COUNTIFS(US!$A:$A, ">=" & DATE(2025,4,1), US!$A:$A, "<=" & EOMONTH(DATE(2025,4,1), 0), US!$H:$H, "Booket til time") -> 0 | U21: =R21/S21 -> #DIV/0! | V21: =R21/T21 -> #DIV/0! | W21: =Y21/R21 -> #DIV/0! | X21: =($S$32*T21)+AC21 -> 0 | Y21: =($S$33*T21)+AC21 -> 0 | Z21: =T21/S21 -> #DIV/0! | AA21: =T21*$S$32 -> 0 | AB21: =COUNTIFS(US!$A:$A, ">=" & DATE(2025,4,1), US!$A:$A, "<=" & EOMONTH(DATE(2025,4,1), 0), US!$G:$G, "Ja") -> 0 | AC21: =AB21*$S$34 -> 0 | AD21: =AB21/S21 -> #DIV/0! | AF21: =S21/AE21 -> #DIV/0!
Q22: Mai | R22: =R49+R65 -> 0 | S22: =COUNTIFS(US!$A:$A, ">=" & DATE(2025,5,1), US!$A:$A, "<=" & EOMONTH(DATE(2025,5,1), 0)) -> 0 | T22: =COUNTIFS(US!$A:$A, ">=" & DATE(2025,5,1), US!$A:$A, "<=" & EOMONTH(DATE(2025,5,1), 0), US!$H:$H, "Booket til time") -> 0 | U22: =R22/S22 -> #DIV/0! | V22: =R22/T22 -> #DIV/0! | W22: =Y22/R22 -> #DIV/0! | X22: =($S$32*T22)+AC22 -> 0 | Y22: =($S$33*T22)+AC22 -> 0 | Z22: =T22/S22 -> #DIV/0! | AA22: =T22*$S$32 -> 0 | AB22: =COUNTIFS(US!$A:$A, ">=" & DATE(2025,5,1), US!$A:$A, "<=" & EOMONTH(DATE(2025,5,1), 0), US!$G:$G, "Ja") -> 0 | AC22: =AB22*$S$34 -> 0 | AD22: =AB22/S22 -> #DIV/0! | AF22: =S22/AE22 -> #DIV/0!
Q23: Juni | R23: =R50+R66 -> 0 | S23: =COUNTIFS(US!$A:$A, ">=" & DATE(2025,6,1), US!$A:$A, "<=" & EOMONTH(DATE(2025,6,1), 0)) -> 0 | T23: =COUNTIFS(US!$A:$A, ">=" & DATE(2025,6,1), US!$A:$A, "<=" & EOMONTH(DATE(2025,6,1), 0), US!$H:$H, "Booket til time") -> 0 | U23: =R23/S23 -> #DIV/0! | V23: =R23/T23 -> #DIV/0! | W23: =Y23/R23 -> #DIV/0! | X23: =($S$32*T23)+AC23 -> 0 | Y23: =($S$33*T23)+AC23 -> 0 | Z23: =T23/S23 -> #DIV/0! | AA23: =T23*$S$32 -> 0 | AB23: =COUNTIFS(US!$A:$A, ">=" & DATE(2025,6,1), US!$A:$A, "<=" & EOMONTH(DATE(2025,6,1), 0), US!$G:$G, "Ja") -> 0 | AC23: =AB23*$S$34 -> 0 | AD23: =AB23/S23 -> #DIV/0! | AF23: =S23/AE23 -> #DIV/0!
Q24: Juli | R24: =R51+R67 -> 0 | S24: =COUNTIFS(US!$A:$A, ">=" & DATE(2025,7,1), US!$A:$A, "<=" & EOMONTH(DATE(2025,7,1), 0)) -> 0 | T24: =COUNTIFS(US!$A:$A, ">=" & DATE(2025,7,1), US!$A:$A, "<=" & EOMONTH(DATE(2025,7,1), 0), US!$H:$H, "Booket til time") -> 0 | U24: =R24/S24 -> #DIV/0! | V24: =R24/T24 -> #DIV/0! | W24: =Y24/R24 -> #DIV/0! | X24: =($S$32*T24)+AC24 -> 0 | Y24: =($S$33*T24)+AC24 -> 0 | Z24: =T24/S24 -> #DIV/0! | AA24: =T24*$S$32 -> 0 | AB24: =COUNTIFS(US!$A:$A, ">=" & DATE(2025,7,1), US!$A:$A, "<=" & EOMONTH(DATE(2025,7,1), 0), US!$G:$G, "Ja") -> 0 | AC24: =AB24*$S$34 -> 0 | AD24: =AB24/S24 -> #DIV/0! | AF24: =S24/AE24 -> #DIV/0!
Q25: August | R25: =R52+R68 -> 0 | S25: =COUNTIFS(US!$A:$A, ">=" & DATE(2025,8,1), US!$A:$A, "<=" & EOMONTH(DATE(2025,8,1), 0)) -> 0 | T25: =COUNTIFS(US!$A:$A, ">=" & DATE(2025,8,1), US!$A:$A, "<=" & EOMONTH(DATE(2025,8,1), 0), US!$H:$H, "Booket til time") -> 0 | U25: =R25/S25 -> #DIV/0! | V25: =R25/T25 -> #DIV/0! | W25: =Y25/R25 -> #DIV/0! | X25: =($S$32*T25)+AC25 -> 0 | Y25: =($S$33*T25)+AC25 -> 0 | Z25: =T25/S25 -> #DIV/0! | AA25: =T25*$S$32 -> 0 | AB25: =COUNTIFS(US!$A:$A, ">=" & DATE(2025,8,1), US!$A:$A, "<=" & EOMONTH(DATE(2025,8,1), 0), US!$G:$G, "Ja") -> 0 | AC25: =AB25*$S$34 -> 0 | AD25: =AB25/S25 -> #DIV/0! | AF25: =S25/AE25 -> #DIV/0!
Q26: September | R26: =R53+R69 -> 0 | S26: =COUNTIFS(US!$A:$A, ">=" & DATE(2025,9,1), US!$A:$A, "<=" & EOMONTH(DATE(2025,9,1), 0)) -> 0 | T26: =COUNTIFS(US!$A:$A, ">=" & DATE(2025,9,1), US!$A:$A, "<=" & EOMONTH(DATE(2025,9,1), 0), US!$H:$H, "Booket til time") -> 0 | U26: =R26/S26 -> #DIV/0! | V26: =R26/T26 -> #DIV/0! | W26: =Y26/R26 -> #DIV/0! | X26: =($S$32*T26)+AC26 -> 0 | Y26: =($S$33*T26)+AC26 -> 0 | Z26: =T26/S26 -> #DIV/0! | AA26: =T26*$S$32 -> 0 | AB26: =COUNTIFS(US!$A:$A, ">=" & DATE(2025,9,1), US!$A:$A, "<=" & EOMONTH(DATE(2025,9,1), 0), US!$G:$G, "Ja") -> 0 | AC26: =AB26*$S$34 -> 0 | AD26: =AB26/S26 -> #DIV/0! | AF26: =S26/AE26 -> #DIV/0!
Q27: Oktober | R27: =R54+R70 -> 6022 | S27: =COUNTIFS(US!$A:$A, ">=" & DATE(2025,10,1), US!$A:$A, "<=" & EOMONTH(DATE(2025,10,1), 0)) -> 0 | T27: =COUNTIFS(US!$A:$A, ">=" & DATE(2025,10,1), US!$A:$A, "<=" & EOMONTH(DATE(2025,10,1), 0), US!$H:$H, "Booket til time") -> 0 | U27: =R27/S27 -> #DIV/0! | V27: =R27/T27 -> #DIV/0! | W27: =Y27/R27 -> 0 | X27: =($S$32*T27)+AC27 -> 0 | Y27: =($S$33*T27)+AC27 -> 0 | Z27: =T27/S27 -> #DIV/0! | AA27: =T27*$S$32 -> 0 | AB27: =COUNTIFS(US!$A:$A, ">=" & DATE(2025,10,1), US!$A:$A, "<=" & EOMONTH(DATE(2025,10,1), 0), US!$G:$G, "Ja") -> 0 | AC27: =AB27*$S$34 -> 0 | AD27: =AB27/S27 -> #DIV/0! | AF27: =S27/AE27 -> #DIV/0!
Q28: November | R28: =R55+R71 -> 0 | S28: =COUNTIFS(US!$A:$A, ">=" & DATE(2025,11,1), US!$A:$A, "<=" & EOMONTH(DATE(2025,11,1), 0)) -> 0 | T28: =COUNTIFS(US!$A:$A, ">=" & DATE(2025,11,1), US!$A:$A, "<=" & EOMONTH(DATE(2025,11,1), 0), US!$H:$H, "Booket til time") -> 0 | U28: =R28/S28 -> #DIV/0! | V28: =R28/T28 -> #DIV/0! | W28: =Y28/R28 -> #DIV/0! | X28: =($S$32*T28)+AC28 -> 0 | Y28: =($S$33*T28)+AC28 -> 0 | Z28: =T28/S28 -> #DIV/0! | AA28: =T28*$S$32 -> 0 | AB28: =COUNTIFS(US!$A:$A, ">=" & DATE(2025,11,1), US!$A:$A, "<=" & EOMONTH(DATE(2025,11,1), 0), US!$G:$G, "Ja") -> 0 | AC28: =AB28*$S$34 -> 0 | AD28: =AB28/S28 -> #DIV/0! | AF28: =S28/AE28 -> #DIV/0!
Q29: Desember | R29: =R56+R72 -> 0 | S29: =COUNTIFS(US!$A:$A, ">=" & DATE(2025,12,1), US!$A:$A, "<=" & EOMONTH(DATE(2025,12,1), 0)) -> 0 | T29: =COUNTIFS(US!$A:$A, ">=" & DATE(2025,12,1), US!$A:$A, "<=" & EOMONTH(DATE(2025,12,1), 0), US!$H:$H, "Booket til time") -> 0 | U29: =R29/S29 -> #DIV/0! | V29: =R29/T29 -> #DIV/0! | W29: =Y29/R29 -> #DIV/0! | X29: =($S$32*T29)+AC29 -> 0 | Y29: =($S$33*T29)+AC29 -> 0 | Z29: =T29/S29 -> #DIV/0! | AA29: =T29*$S$32 -> 0 | AB29: =COUNTIFS(US!$A:$A, ">=" & DATE(2025,12,1), US!$A:$A, "<=" & EOMONTH(DATE(2025,12,1), 0), US!$G:$G, "Ja") -> 0 | AC29: =AB29*$S$34 -> 0 | AD29: =AB29/S29 -> #DIV/0! | AF29: =S29/AE29 -> #DIV/0!
Q30: Totalt | R30: =SUM(R18:R29) -> 6022 | S30: =SUM(S18:S29) -> 0 | T30: =SUM(T18:T29) -> 0 | U30: =R30/S30 -> #DIV/0! | V30: =R30/T30 -> #DIV/0! | W30: =Y30/R30 -> 0 | X30: =SUM(X18:X29) -> 0 | Y30: =SUM(Y18:Y29) -> 0 | Z30: =T30/S30 -> #DIV/0! | AA30: =SUM(AA18:AA29) -> 0 | AB30: =SUM(AB18:AB29) -> 0 | AC30: =SUM(AC18:AC29) -> 0 | AD30: =AB30/S30 -> #DIV/0! | AE30: =SUM(AE18:AE29) -> 0 | AF30: =S30/AE30 -> #DIV/0!
Q32: Omsetning | S32: 590 | U32: URL
Q33: Potensiell omsetning | S33: 2000 | U33: {=UNIQUE(US!Z:Z)} -> post url
Q34: Oppsalg tannbleking | S34: 2490 | X34: =COUNTIF(US!Z:Z,U34) -> 0
